Exception on /api/v1.0/hello/toshi [GET]
Traceback (most recent call last):
  File "/Users/toshihirokuboi/git/my-SiameseNet/venv/lib/python3.7/site-packages/flask/app.py", line 2446, in wsgi_app
    response = self.full_dispatch_request()
  File "/Users/toshihirokuboi/git/my-SiameseNet/venv/lib/python3.7/site-packages/flask/app.py", line 1951, in full_dispatch_request
    rv = self.handle_user_exception(e)
  File "/Users/toshihirokuboi/git/my-SiameseNet/venv/lib/python3.7/site-packages/flask/app.py", line 1820, in handle_user_exception
    reraise(exc_type, exc_value, tb)
  File "/Users/toshihirokuboi/git/my-SiameseNet/venv/lib/python3.7/site-packages/flask/_compat.py", line 39, in reraise
    raise value
  File "/Users/toshihirokuboi/git/my-SiameseNet/venv/lib/python3.7/site-packages/flask/app.py", line 1949, in full_dispatch_request
    rv = self.dispatch_request()
  File "/Users/toshihirokuboi/git/my-SiameseNet/venv/lib/python3.7/site-packages/flask/app.py", line 1935, in dispatch_request
    return self.view_functions[rule.endpoint](**req.view_args)
  File "/Users/toshihirokuboi/git/my-SiameseNet/app/api_1_0/api_server.py", line 23, in hello_world
    recognizer.load_model()
AttributeError: 'Recognizer' object has no attribute 'load_model'
Exception on /api/v1.0/get_wine/gewurz.JPG [GET]
Traceback (most recent call last):
  File "/Users/toshihirokuboi/git/my-SiameseNet/venv/lib/python3.7/site-packages/flask/app.py", line 2446, in wsgi_app
    response = self.full_dispatch_request()
  File "/Users/toshihirokuboi/git/my-SiameseNet/venv/lib/python3.7/site-packages/flask/app.py", line 1951, in full_dispatch_request
    rv = self.handle_user_exception(e)
  File "/Users/toshihirokuboi/git/my-SiameseNet/venv/lib/python3.7/site-packages/flask/app.py", line 1820, in handle_user_exception
    reraise(exc_type, exc_value, tb)
  File "/Users/toshihirokuboi/git/my-SiameseNet/venv/lib/python3.7/site-packages/flask/_compat.py", line 39, in reraise
    raise value
  File "/Users/toshihirokuboi/git/my-SiameseNet/venv/lib/python3.7/site-packages/flask/app.py", line 1949, in full_dispatch_request
    rv = self.dispatch_request()
  File "/Users/toshihirokuboi/git/my-SiameseNet/venv/lib/python3.7/site-packages/flask/app.py", line 1935, in dispatch_request
    return self.view_functions[rule.endpoint](**req.view_args)
  File "/Users/toshihirokuboi/git/my-SiameseNet/app/api_1_0/api_server.py", line 30, in get_wine
    label, score = recognizer.predict(imagefile)
  File "/Users/toshihirokuboi/git/my-SiameseNet/app/net/recognizer.py", line 57, in predict
    test_images, names = model.preprocess_images(filepath)
NameError: name 'model' is not defined
Exception on /api/v1.0/get_wine/gewurz.JPG [GET]
Traceback (most recent call last):
  File "/Users/toshihirokuboi/git/my-SiameseNet/venv/lib/python3.7/site-packages/flask/app.py", line 2446, in wsgi_app
    response = self.full_dispatch_request()
  File "/Users/toshihirokuboi/git/my-SiameseNet/venv/lib/python3.7/site-packages/flask/app.py", line 1951, in full_dispatch_request
    rv = self.handle_user_exception(e)
  File "/Users/toshihirokuboi/git/my-SiameseNet/venv/lib/python3.7/site-packages/flask/app.py", line 1820, in handle_user_exception
    reraise(exc_type, exc_value, tb)
  File "/Users/toshihirokuboi/git/my-SiameseNet/venv/lib/python3.7/site-packages/flask/_compat.py", line 39, in reraise
    raise value
  File "/Users/toshihirokuboi/git/my-SiameseNet/venv/lib/python3.7/site-packages/flask/app.py", line 1949, in full_dispatch_request
    rv = self.dispatch_request()
  File "/Users/toshihirokuboi/git/my-SiameseNet/venv/lib/python3.7/site-packages/flask/app.py", line 1935, in dispatch_request
    return self.view_functions[rule.endpoint](**req.view_args)
  File "/Users/toshihirokuboi/git/my-SiameseNet/app/api_1_0/api_server.py", line 33, in get_wine
    return jsonify(reply),status_code
  File "/Users/toshihirokuboi/git/my-SiameseNet/venv/lib/python3.7/site-packages/flask/json/__init__.py", line 370, in jsonify
    dumps(data, indent=indent, separators=separators) + "\n",
  File "/Users/toshihirokuboi/git/my-SiameseNet/venv/lib/python3.7/site-packages/flask/json/__init__.py", line 211, in dumps
    rv = _json.dumps(obj, **kwargs)
  File "/usr/local/Cellar/python/3.7.2_1/Frameworks/Python.framework/Versions/3.7/lib/python3.7/json/__init__.py", line 238, in dumps
    **kw).encode(obj)
  File "/usr/local/Cellar/python/3.7.2_1/Frameworks/Python.framework/Versions/3.7/lib/python3.7/json/encoder.py", line 199, in encode
    chunks = self.iterencode(o, _one_shot=True)
  File "/usr/local/Cellar/python/3.7.2_1/Frameworks/Python.framework/Versions/3.7/lib/python3.7/json/encoder.py", line 257, in iterencode
    return _iterencode(o, 0)
  File "/Users/toshihirokuboi/git/my-SiameseNet/venv/lib/python3.7/site-packages/flask/json/__init__.py", line 100, in default
    return _json.JSONEncoder.default(self, o)
  File "/usr/local/Cellar/python/3.7.2_1/Frameworks/Python.framework/Versions/3.7/lib/python3.7/json/encoder.py", line 179, in default
    raise TypeError(f'Object of type {o.__class__.__name__} '
TypeError: Object of type float32 is not JSON serializable
Exception on /api/v1.0/get_wine/gewurz.JPG [GET]
Traceback (most recent call last):
  File "/Users/toshihirokuboi/git/my-SiameseNet/venv/lib/python3.7/site-packages/flask/app.py", line 2446, in wsgi_app
    response = self.full_dispatch_request()
  File "/Users/toshihirokuboi/git/my-SiameseNet/venv/lib/python3.7/site-packages/flask/app.py", line 1951, in full_dispatch_request
    rv = self.handle_user_exception(e)
  File "/Users/toshihirokuboi/git/my-SiameseNet/venv/lib/python3.7/site-packages/flask/app.py", line 1820, in handle_user_exception
    reraise(exc_type, exc_value, tb)
  File "/Users/toshihirokuboi/git/my-SiameseNet/venv/lib/python3.7/site-packages/flask/_compat.py", line 39, in reraise
    raise value
  File "/Users/toshihirokuboi/git/my-SiameseNet/venv/lib/python3.7/site-packages/flask/app.py", line 1949, in full_dispatch_request
    rv = self.dispatch_request()
  File "/Users/toshihirokuboi/git/my-SiameseNet/venv/lib/python3.7/site-packages/flask/app.py", line 1935, in dispatch_request
    return self.view_functions[rule.endpoint](**req.view_args)
  File "/Users/toshihirokuboi/git/my-SiameseNet/app/api_1_0/api_server.py", line 33, in get_wine
    return jsonify(reply),status_code
  File "/Users/toshihirokuboi/git/my-SiameseNet/venv/lib/python3.7/site-packages/flask/json/__init__.py", line 370, in jsonify
    dumps(data, indent=indent, separators=separators) + "\n",
  File "/Users/toshihirokuboi/git/my-SiameseNet/venv/lib/python3.7/site-packages/flask/json/__init__.py", line 211, in dumps
    rv = _json.dumps(obj, **kwargs)
  File "/usr/local/Cellar/python/3.7.2_1/Frameworks/Python.framework/Versions/3.7/lib/python3.7/json/__init__.py", line 238, in dumps
    **kw).encode(obj)
  File "/usr/local/Cellar/python/3.7.2_1/Frameworks/Python.framework/Versions/3.7/lib/python3.7/json/encoder.py", line 199, in encode
    chunks = self.iterencode(o, _one_shot=True)
  File "/usr/local/Cellar/python/3.7.2_1/Frameworks/Python.framework/Versions/3.7/lib/python3.7/json/encoder.py", line 257, in iterencode
    return _iterencode(o, 0)
  File "/Users/toshihirokuboi/git/my-SiameseNet/venv/lib/python3.7/site-packages/flask/json/__init__.py", line 100, in default
    return _json.JSONEncoder.default(self, o)
  File "/usr/local/Cellar/python/3.7.2_1/Frameworks/Python.framework/Versions/3.7/lib/python3.7/json/encoder.py", line 179, in default
    raise TypeError(f'Object of type {o.__class__.__name__} '
TypeError: Object of type float32 is not JSON serializable
